# -*- coding: utf-8 -*-
# Part of Odoo. See LICENSE file for full copyright and licensing details.

from odoo import models, _
from odoo.exceptions import UserError
from odoo.tools.misc import clean_context

class ProductReplenish(models.TransientModel):
    _inherit = 'product.replenish'
    
    def launch_replenishment(self):
        uom_reference = self.product_id.uom_id
        self.quantity = self.product_uom_id._compute_quantity(self.quantity, uom_reference)
        try:
            self.env['procurement.group'].with_context(clean_context(self.env.context)).run([
                self.env['procurement.group'].Procurement(
                    self.product_id,
                    self.quantity,
                    uom_reference,
                    self.warehouse_id.lot_stock_id,  # Location
                    _("Manual Replenishment"),  # Name
                    _("Manual Replenishment"),  # Origin
                    self.warehouse_id.company_id,
                    self.product_id.lumber_inch,
                    self.product_id.m3_piece,
                    self.product_id.metric_volum,
                    self._prepare_run_values()  # Values
                )
            ])
        except UserError as error:
            raise UserError(error)
